2025-03-14 17:48:53,503 - INFO - ============================= test session starts =============================
2025-03-14 17:48:53,505 - INFO - platform win32 -- Python 3.11.9, pytest-8.3.5, pluggy-1.5.0 -- E:\automation\venv\Scripts\python.exe
2025-03-14 17:48:53,506 - INFO - cachedir: .pytest_cache
2025-03-14 17:48:53,509 - INFO - rootdir: E:\automation
2025-03-14 17:48:53,510 - INFO - plugins: allure-pytest-2.13.5
2025-03-14 17:48:53,705 - INFO - collecting ... collected 0 items / 1 error
2025-03-14 17:48:53,706 - INFO - 
2025-03-14 17:48:53,709 - INFO - =================================== ERRORS ====================================
2025-03-14 17:48:53,710 - INFO - _____________________ ERROR collecting tests/test_api.py ______________________
2025-03-14 17:48:53,713 - INFO - ImportError while importing test module 'E:\automation\tests\test_api.py'.
2025-03-14 17:48:53,715 - INFO - Hint: make sure your test modules/packages have valid Python names.
2025-03-14 17:48:53,716 - INFO - Traceback:
2025-03-14 17:48:53,719 - INFO - C:\Program Files\WindowsApps\PythonSoftwareFoundation.Python.3.11_3.11.2544.0_x64__qbz5n2kfra8p0\Lib\importlib\__init__.py:126: in import_module
2025-03-14 17:48:53,720 - INFO - return _bootstrap._gcd_import(name[level:], package, level)
2025-03-14 17:48:53,722 - INFO - tests\test_api.py:2: in <module>
2025-03-14 17:48:53,724 - INFO - import requests
2025-03-14 17:48:53,726 - INFO - E   ModuleNotFoundError: No module named 'requests'
2025-03-14 17:48:53,728 - INFO - =========================== short test summary info ===========================
2025-03-14 17:48:53,730 - INFO - ERROR tests/test_api.py
2025-03-14 17:48:53,732 - INFO - !!!!!!!!!!!!!!!!!!! Interrupted: 1 error during collection !!!!!!!!!!!!!!!!!!!!
2025-03-14 17:48:53,738 - INFO - ============================== 1 error in 0.20s ===============================
2025-03-14 17:52:34,042 - INFO - ============================= test session starts =============================
2025-03-14 17:52:34,044 - INFO - platform win32 -- Python 3.11.9, pytest-8.3.5, pluggy-1.5.0 -- E:\automation\venv\Scripts\python.exe
2025-03-14 17:52:34,045 - INFO - cachedir: .pytest_cache
2025-03-14 17:52:34,047 - INFO - rootdir: E:\automation
2025-03-14 17:52:34,048 - INFO - plugins: allure-pytest-2.13.5
2025-03-14 17:52:34,986 - INFO - collecting ... collected 0 items / 1 error
2025-03-14 17:52:34,988 - INFO - 
2025-03-14 17:52:34,989 - INFO - =================================== ERRORS ====================================
2025-03-14 17:52:34,991 - INFO - _____________________ ERROR collecting tests/test_api.py ______________________
2025-03-14 17:52:34,993 - INFO - tests\test_api.py:82: in <module>
2025-03-14 17:52:34,995 - INFO - class TestApiIntegration:
2025-03-14 17:52:34,996 - INFO - tests\test_api.py:119: in TestApiIntegration
2025-03-14 17:52:34,997 - INFO - @allure.severity(allure.severity_level.HIGH)
2025-03-14 17:52:34,999 - INFO - C:\Program Files\WindowsApps\PythonSoftwareFoundation.Python.3.11_3.11.2544.0_x64__qbz5n2kfra8p0\Lib\enum.py:786: in __getattr__
2025-03-14 17:52:35,001 - INFO - raise AttributeError(name) from None
2025-03-14 17:52:35,008 - INFO - E   AttributeError: HIGH
2025-03-14 17:52:35,010 - INFO - =========================== short test summary info ===========================
2025-03-14 17:52:35,012 - INFO - ERROR tests/test_api.py - AttributeError: HIGH
2025-03-14 17:52:35,013 - INFO - !!!!!!!!!!!!!!!!!!! Interrupted: 1 error during collection !!!!!!!!!!!!!!!!!!!!
2025-03-14 17:52:35,016 - INFO - ============================== 1 error in 0.95s ===============================
